Traceback (most recent call last):
  File "/Users/olgascrivner/anaconda3/lib/python3.7/site-packages/jupyter_cache/executors/utils.py", line 56, in single_nb_execution
    record_timing=False,
  File "/Users/olgascrivner/anaconda3/lib/python3.7/site-packages/nbclient/client.py", line 1082, in execute
    return NotebookClient(nb=nb, resources=resources, km=km, **kwargs).execute()
  File "/Users/olgascrivner/anaconda3/lib/python3.7/site-packages/nbclient/util.py", line 74, in wrapped
    return just_run(coro(*args, **kwargs))
  File "/Users/olgascrivner/anaconda3/lib/python3.7/site-packages/nbclient/util.py", line 53, in just_run
    return loop.run_until_complete(coro)
  File "/Users/olgascrivner/anaconda3/lib/python3.7/asyncio/base_events.py", line 573, in run_until_complete
    return future.result()
  File "/Users/olgascrivner/anaconda3/lib/python3.7/site-packages/nbclient/client.py", line 536, in async_execute
    cell, index, execution_count=self.code_cells_executed + 1
  File "/Users/olgascrivner/anaconda3/lib/python3.7/site-packages/nbclient/client.py", line 827, in async_execute_cell
    self._check_raise_for_error(cell, exec_reply)
  File "/Users/olgascrivner/anaconda3/lib/python3.7/site-packages/nbclient/client.py", line 735, in _check_raise_for_error
    raise CellExecutionError.from_cell_and_msg(cell, exec_reply['content'])
nbclient.exceptions.CellExecutionError: An error occurred while executing the following cell:
------------------
X_train, X_test = train_test_split(tokens_sentences, test_size=0.2, random_state=1)
------------------

[0;31m---------------------------------------------------------------------------[0m
[0;31mValueError[0m                                Traceback (most recent call last)
[0;32m<ipython-input-56-ca1179889233>[0m in [0;36m<module>[0;34m[0m
[0;32m----> 1[0;31m [0mX_train[0m[0;34m,[0m [0mX_test[0m [0;34m=[0m [0mtrain_test_split[0m[0;34m([0m[0mtokens_sentences[0m[0;34m,[0m [0mtest_size[0m[0;34m=[0m[0;36m0.2[0m[0;34m,[0m [0mrandom_state[0m[0;34m=[0m[0;36m1[0m[0;34m)[0m[0;34m[0m[0;34m[0m[0m
[0m
[0;32m~/anaconda3/lib/python3.7/site-packages/sklearn/model_selection/_split.py[0m in [0;36mtrain_test_split[0;34m(*arrays, **options)[0m
[1;32m   2129[0m     [0mn_samples[0m [0;34m=[0m [0m_num_samples[0m[0;34m([0m[0marrays[0m[0;34m[[0m[0;36m0[0m[0;34m][0m[0;34m)[0m[0;34m[0m[0;34m[0m[0m
[1;32m   2130[0m     n_train, n_test = _validate_shuffle_split(n_samples, test_size, train_size,
[0;32m-> 2131[0;31m                                               default_test_size=0.25)
[0m[1;32m   2132[0m [0;34m[0m[0m
[1;32m   2133[0m     [0;32mif[0m [0mshuffle[0m [0;32mis[0m [0;32mFalse[0m[0;34m:[0m[0;34m[0m[0;34m[0m[0m

[0;32m~/anaconda3/lib/python3.7/site-packages/sklearn/model_selection/_split.py[0m in [0;36m_validate_shuffle_split[0;34m(n_samples, test_size, train_size, default_test_size)[0m
[1;32m   1812[0m             [0;34m'resulting train set will be empty. Adjust any of the '[0m[0;34m[0m[0;34m[0m[0m
[1;32m   1813[0m             'aforementioned parameters.'.format(n_samples, test_size,
[0;32m-> 1814[0;31m                                                 train_size)
[0m[1;32m   1815[0m         )
[1;32m   1816[0m [0;34m[0m[0m

[0;31mValueError[0m: With n_samples=1, test_size=0.2 and train_size=None, the resulting train set will be empty. Adjust any of the aforementioned parameters.
ValueError: With n_samples=1, test_size=0.2 and train_size=None, the resulting train set will be empty. Adjust any of the aforementioned parameters.

